Workbook

Sheet counts
A1: Index_pegRNA | B1: Target actual | C1: Rep1_B20 | D1: Rep1_B40 | E1: Rep1_Bulk | F1: Rep1_T20 | G1: Rep1_T40 | H1: Rep2_B20 | I1: Rep2_B40 | J1: Rep2_Bulk | K1: Rep2_T20 | L1: Rep2_T40 | M1: Rep3_B20 | N1: Rep3_B40 | O1: Rep3_Bulk | P1: Rep3_T20 | Q1: Rep3_T40 | R1: Rep4_B20 | S1: Rep4_B40 | T1: Rep4_Bulk | U1: Rep4_T20 | V1: Rep4_T40
A2: 1 | B2: G137K | C2: 1300 | D2: 1207 | E2: 984 | F2: 1590 | G2: 775 | H2: 669 | I2: 489 | J2: 335 | K2: 916 | L2: 546 | M2: 1358 | N2: 667 | O2: 688 | P2: 503 | Q2: 321 | R2: 1080 | S2: 426 | T2: 1286 | U2: 366 | V2: 1028
A3: 2 | B3: G137N | C3: 494 | D3: 397 | E3: 217 | F3: 459 | G3: 169 | H3: 1243 | I3: 864 | J3: 323 | K3: 1725 | L3: 1310 | M3: 1061 | N3: 782 | O3: 680 | P3: 245 | Q3: 315 | R3: 317 | S3: 164 | T3: 290 | U3: 59 | V3: 408
A4: 3 | B4: G137T | C4: 1640 | D4: 2162 | E4: 831 | F4: 1266 | G4: 856 | H4: 818 | I4: 1068 | J4: 493 | K4: 2035 | L4: 867 | M4: 1252 | N4: 817 | O4: 177 | P4: 420 | Q4: 370 | R4: 2227 | S4: 554 | T4: 1842 | U4: 571 | V4: 2276
A5: 4 | B5: G137R | C5: 1342 | D5: 1404 | E5: 779 | F5: 979 | G5: 875 | H5: 1025 | I5: 754 | J5: 386 | K5: 1267 | L5: 1010 | M5: 1076 | N5: 1165 | O5: 565 | P5: 538 | Q5: 411 | R5: 1802 | S5: 552 | T5: 1453 | U5: 713 | V5: 1564
A6: 5 | B6: G137S | C6: 1404 | D6: 1655 | E6: 994 | F6: 1458 | G6: 927 | H6: 1333 | I6: 1205 | J6: 584 | K6: 1670 | L6: 1101 | M6: 1497 | N6: 1160 | O6: 535 | P6: 608 | Q6: 396 | R6: 675 | S6: 331 | T6: 669 | U6: 194 | V6: 582
A7: 6 | B7: G137I | C7: 1480 | D7: 1841 | E7: 655 | F7: 1111 | G7: 930 | H7: 1741 | I7: 1407 | J7: 709 | K7: 2197 | L7: 1774 | M7: 721 | N7: 566 | O7: 255 | P7: 291 | Q7: 196 | R7: 1005 | S7: 399 | T7: 1165 | U7: 438 | V7: 1217
A8: 7 | B8: G137M | C8: 1367 | D8: 2098 | E8: 1316 | F8: 1390 | G8: 693 | H8: 875 | I8: 1129 | J8: 648 | K8: 969 | L8: 876 | M8: 2355 | N8: 1873 | O8: 875 | P8: 1034 | Q8: 800 | R8: 1163 | S8: 352 | T8: 1026 | U8: 444 | V8: 1238
A9: 8 | B9: G137Q | C9: 766 | D9: 1135 | E9: 489 | F9: 875 | G9: 526 | H9: 1365 | I9: 1136 | J9: 248 | K9: 1873 | L9: 1205 | M9: 1479 | N9: 791 | O9: 326 | P9: 381 | Q9: 278 | R9: 719 | S9: 320 | T9: 587 | U9: 312 | V9: 865
A10: 9 | B10: G137H | C10: 683 | D10: 994 | E10: 556 | F10: 705 | G10: 501 | H10: 1028 | I10: 911 | J10: 440 | K10: 1382 | L10: 726 | M10: 1653 | N10: 1219 | O10: 616 | P10: 632 | Q10: 312 | R10: 886 | S10: 319 | T10: 1061 | U10: 402 | V10: 1114
A11: 10 | B11: G137P | C11: 2677 | D11: 2470 | E11: 1152 | F11: 2175 | G11: 1409 | H11: 1140 | I11: 1045 | J11: 666 | K11: 1625 | L11: 1112 | M11: 2482 | N11: 1850 | O11: 1118 | P11: 988 | Q11: 779 | R11: 1325 | S11: 428 | T11: 918 | U11: 321 | V11: 793
A12: 11 | B12: G137L | C12: 1358 | D12: 1688 | E12: 872 | F12: 1390 | G12: 571 | H12: 909 | I12: 782 | J12: 318 | K12: 1307 | L12: 756 | M12: 1499 | N12: 1194 | O12: 697 | P12: 810 | Q12: 331 | R12: 1555 | S12: 756 | T12: 1595 | U12: 846 | V12: 1806
A13: 12 | B13: G137E | C13: 1603 | D13: 1870 | E13: 894 | F13: 984 | G13: 557 | H13: 1824 | I13: 1484 | J13: 932 | K13: 3040 | L13: 1332 | M13: 1541 | N13: 1104 | O13: 678 | P13: 354 | Q13: 311 | R13: 507 | S13: 133 | T13: 440 | U13: 176 | V13: 674
... A1505: 1556 | B1505: S213R | C1505: 225 | D1505: 119 | E1505: 48 | F1505: 284 | G1505: 114 | H1505: 212 | I1505: 105 | J1505: 115 | K1505: 164 | L1505: 221 | M1505: 563 | N1505: 536 | O1505: 341 | P1505: 94 | Q1505: 168 | R1505: 302 | S1505: 146 | T1505: 284 | U1505: 77 | V1505: 216
A1506: 1557 | B1506: 0 | C1506: 167 | D1506: 417 | E1506: 187 | F1506: 295 | G1506: 158 | H1506: 155 | I1506: 20 | J1506: 34 | K1506: 70 | L1506: 63 | M1506: 171 | N1506: 118 | O1506: 59 | P1506: 80 | Q1506: 108 | R1506: 1162 | S1506: 516 | T1506: 1135 | U1506: 468 | V1506: 1361
A1507: 1558 | B1507: S213I | C1507: 354 | D1507: 454 | E1507: 204 | F1507: 731 | G1507: 191 | H1507: 140 | I1507: 256 | J1507: 0 | K1507: 111 | L1507: 87 | M1507: 316 | N1507: 177 | O1507: 123 | P1507: 203 | Q1507: 140 | R1507: 464 | S1507: 130 | T1507: 386 | U1507: 329 | V1507: 444
A1508: 1559 | B1508: S213M | C1508: 594 | D1508: 577 | E1508: 345 | F1508: 1116 | G1508: 680 | H1508: 353 | I1508: 78 | J1508: 64 | K1508: 345 | L1508: 112 | M1508: 156 | N1508: 89 | O1508: 0 | P1508: 18 | Q1508: 43 | R1508: 295 | S1508: 93 | T1508: 447 | U1508: 62 | V1508: 264
A1509: 1560 | B1509: S213Q | C1509: 288 | D1509: 244 | E1509: 48 | F1509: 232 | G1509: 141 | H1509: 84 | I1509: 124 | J1509: 74 | K1509: 185 | L1509: 213 | M1509: 955 | N1509: 812 | O1509: 234 | P1509: 320 | Q1509: 312 | R1509: 520 | S1509: 207 | T1509: 232 | U1509: 167 | V1509: 480
A1510: 1561 | B1510: S213H | C1510: 99 | D1510: 197 | E1510: 136 | F1510: 408 | G1510: 196 | H1510: 201 | I1510: 294 | J1510: 200 | K1510: 440 | L1510: 218 | M1510: 481 | N1510: 313 | O1510: 139 | P1510: 174 | Q1510: 152 | R1510: 210 | S1510: 63 | T1510: 229 | U1510: 0 | V1510: 199
A1511: 1562 | B1511: S213P | C1511: 1031 | D1511: 1051 | E1511: 172 | F1511: 634 | G1511: 531 | H1511: 219 | I1511: 189 | J1511: 21 | K1511: 263 | L1511: 198 | M1511: 1735 | N1511: 742 | O1511: 511 | P1511: 330 | Q1511: 127 | R1511: 356 | S1511: 120 | T1511: 163 | U1511: 70 | V1511: 228
A1512: 1563 | B1512: S213L | C1512: 292 | D1512: 709 | E1512: 409 | F1512: 1084 | G1512: 456 | H1512: 219 | I1512: 149 | J1512: 88 | K1512: 913 | L1512: 366 | M1512: 60 | N1512: 64 | O1512: 92 | P1512: 66 | Q1512: 29 | R1512: 129 | S1512: 120 | T1512: 478 | U1512: 149 | V1512: 262
A1513: 1564 | B1513: S213E | C1513: 318 | D1513: 307 | E1513: 200 | F1513: 314 | G1513: 266 | H1513: 432 | I1513: 265 | J1513: 0 | K1513: 138 | L1513: 7 | M1513: 242 | N1513: 200 | O1513: 37 | P1513: 103 | Q1513: 98 | R1513: 82 | S1513: 88 | T1513: 141 | U1513: 38 | V1513: 186
A1514: 1565 | B1514: S213D | C1514: 429 | D1514: 393 | E1514: 136 | F1514: 265 | G1514: 112 | H1514: 96 | I1514: 70 | J1514: 84 | K1514: 157 | L1514: 26 | M1514: 283 | N1514: 434 | O1514: 212 | P1514: 151 | Q1514: 133 | R1514: 174 | S1514: 78 | T1514: 80 | U1514: 83 | V1514: 203
A1515: 1566 | B1515: S213A | C1515: 293 | D1515: 371 | E1515: 306 | F1515: 376 | G1515: 313 | H1515: 327 | I1515: 349 | J1515: 248 | K1515: 698 | L1515: 503 | M1515: 552 | N1515: 251 | O1515: 173 | P1515: 208 | Q1515: 152 | R1515: 532 | S1515: 263 | T1515: 743 | U1515: 409 | V1515: 927
A1516: 1567 | B1516: S213G | C1516: 640 | D1516: 716 | E1516: 542 | F1516: 590 | G1516: 507 | H1516: 34 | I1516: 39 | J1516: 0 | K1516: 122 | L1516: 97 | M1516: 207 | N1516: 134 | O1516: 0 | P1516: 195 | Q1516: 134 | R1516: 157 | S1516: 113 | T1516: 168 | U1516: 72 | V1516: 304
A1517: 1568 | B1517: S213V | C1517: 552 | D1517: 483 | E1517: 276 | F1517: 735 | G1517: 428 | H1517: 61 | I1517: 49 | J1517: 50 | K1517: 158 | L1517: 44 | M1517: 356 | N1517: 463 | O1517: 258 | P1517: 348 | Q1517: 182 | R1517: 274 | S1517: 59 | T1517: 113 | U1517: 39 | V1517: 235
A1518: 1569 | B1518: S213_ | C1518: 483 | D1518: 471 | E1518: 70 | F1518: 70 | G1518: 93 | H1518: 216 | I1518: 177 | J1518: 86 | K1518: 139 | L1518: 93 | M1518: 201 | N1518: 193 | O1518: 90 | P1518: 31 | Q1518: 33 | R1518: 1552 | S1518: 393 | T1518: 720 | U1518: 111 | V1518: 775
... A1647: 1698 | B1647: G219F | C1647: 923 | D1647: 1041 | E1647: 544 | F1647: 925 | G1647: 600 | H1647: 416 | I1647: 531 | J1647: 630 | K1647: 833 | L1647: 406 | M1647: 801 | N1647: 645 | O1647: 404 | P1647: 402 | Q1647: 351 | R1647: 551 | S1647: 141 | T1647: 627 | U1647: 232 | V1647: 511
A1649: Sum | C1649: =SUM(C2:C1647) -> 1219730 | D1649: =SUM(D2:D1647) -> 1432237 | E1649: =SUM(E2:E1647) -> 668464 | F1649: =SUM(F2:F1647) -> 1198022 | G1649: =SUM(G2:G1647) -> 768580 | H1649: =SUM(H2:H1647) -> 1006133 | I1649: =SUM(I2:I1647) -> 853354 | J1649: =SUM(J2:J1647) -> 412628 | ... V1649: =SUM(V2:V1647) -> 1207087

Sheet edited counts
A1: Index_pegRNA | B1: Target actual | C1: Rep1_B20 | D1: Rep1_B40 | E1: Rep1_Bulk | F1: Rep1_T20 | G1: Rep1_T40 | H1: Rep2_B20 | I1: Rep2_B40 | J1: Rep2_Bulk | K1: Rep2_T20 | L1: Rep2_T40 | M1: Rep3_B20 | N1: Rep3_B40 | O1: Rep3_Bulk | P1: Rep3_T20 | Q1: Rep3_T40 | R1: Rep4_B20 | S1: Rep4_B40 | T1: Rep4_Bulk | U1: Rep4_T20 | V1: Rep4_T40
A2: 1 | B2: G137K | C2: =counts!C2*edit_fraction!C2 -> 149.78261 | D2: =counts!D2*edit_fraction!D2 -> 82.348928 | E2: =counts!E2*edit_fraction!E2 -> 59.147541 | F2: =counts!F2*edit_fraction!F2 -> 143.31633 | G2: =counts!G2*edit_fraction!G2 -> 117.31651 | H2: =counts!H2*edit_fraction!H2 -> 68.82716 | I2: =counts!I2*edit_fraction!I2 -> 51.204188 | J2: =counts!J2*edit_fraction!J2 -> 5.234375 | ... V2: =counts!V2*edit_fraction!V2 -> 140.04638
A3: 2 | B3: G137N | C3: =counts!C3*edit_fraction!C3 -> 76.620408 | D3: =counts!D3*edit_fraction!D3 -> 68.234375 | E3: =counts!E3*edit_fraction!E3 -> 28.12963 | F3: =counts!F3*edit_fraction!F3 -> 106.79703 | G3: =counts!G3*edit_fraction!G3 -> 21.392405 | H3: =counts!H3*edit_fraction!H3 -> 229.2418 | I3: =counts!I3*edit_fraction!I3 -> 179.7707 | J3: =counts!J3*edit_fraction!J3 -> 41.613497 | ... V3: =counts!V3*edit_fraction!V3 -> 100.90323
A4: 3 | B4: G137T | C4: =counts!C4*edit_fraction!C4 -> 455.00603 | D4: =counts!D4*edit_fraction!D4 -> 455.04952 | E4: =counts!E4*edit_fraction!E4 -> 129.31988 | F4: =counts!F4*edit_fraction!F4 -> 256.45659 | G4: =counts!G4*edit_fraction!G4 -> 251.93311 | H4: =counts!H4*edit_fraction!H4 -> 212.73993 | I4: =counts!I4*edit_fraction!I4 -> 250.46904 | J4: =counts!J4*edit_fraction!J4 -> 108.87083 | ... V4: =counts!V4*edit_fraction!V4 -> 961.69014
A5: 4 | B5: G137R | C5: =counts!C5*edit_fraction!C5 -> 79.835694 | D5: =counts!D5*edit_fraction!D5 -> 101.41761 | E5: =counts!E5*edit_fraction!E5 -> 16.297071 | F5: =counts!F5*edit_fraction!F5 -> 70.821277 | G5: =counts!G5*edit_fraction!G5 -> 20.348837 | H5: =counts!H5*edit_fraction!H5 -> 38.278008 | I5: =counts!I5*edit_fraction!I5 -> 82.630137 | J5: =counts!J5*edit_fraction!J5 -> 14.475 | ... V5: =counts!V5*edit_fraction!V5 -> 224.22939
A6: 5 | B6: G137S | C6: =counts!C6*edit_fraction!C6 -> 207.72718 | D6: =counts!D6*edit_fraction!D6 -> 223.57018 | E6: =counts!E6*edit_fraction!E6 -> 109.43119 | F6: =counts!F6*edit_fraction!F6 -> 223.68577 | G6: =counts!G6*edit_fraction!G6 -> 142.85959 | H6: =counts!H6*edit_fraction!H6 -> 335.37261 | I6: =counts!I6*edit_fraction!I6 -> 355.28866 | J6: =counts!J6*edit_fraction!J6 -> 145.68602 | ... V6: =counts!V6*edit_fraction!V6 -> 147.36061
A7: 6 | B7: G137I | C7: =counts!C7*edit_fraction!C7 -> 295.62814 | D7: =counts!D7*edit_fraction!D7 -> 415.36902 | E7: =counts!E7*edit_fraction!E7 -> 84.442509 | F7: =counts!F7*edit_fraction!F7 -> 345.28663 | G7: =counts!G7*edit_fraction!G7 -> 157.41648 | H7: =counts!H7*edit_fraction!H7 -> 223.7842 | I7: =counts!I7*edit_fraction!I7 -> 177.19077 | J7: =counts!J7*edit_fraction!J7 -> 82.987277 | ... V7: =counts!V7*edit_fraction!V7 -> 221.4761
A8: 7 | B8: G137M | C8: =counts!C8*edit_fraction!C8 -> 66.955102 | D8: =counts!D8*edit_fraction!D8 -> 178.55319 | E8: =counts!E8*edit_fraction!E8 -> 69.003745 | F8: =counts!F8*edit_fraction!F8 -> 117.46479 | G8: =counts!G8*edit_fraction!G8 -> 25.477941 | H8: =counts!H8*edit_fraction!H8 -> 62.5 | I8: =counts!I8*edit_fraction!I8 -> 130.46222 | J8: =counts!J8*edit_fraction!J8 -> 67.5 | ... V8: =counts!V8*edit_fraction!V8 -> 103.16667
A9: 8 | B9: G137Q | C9: =counts!C9*edit_fraction!C9 -> 34.818182 | D9: =counts!D9*edit_fraction!D9 -> 18.380567 | E9: =counts!E9*edit_fraction!E9 -> 13.71028 | F9: =counts!F9*edit_fraction!F9 -> 24.857955 | G9: =counts!G9*edit_fraction!G9 -> 5.1568627 | H9: =counts!H9*edit_fraction!H9 -> 0 | I9: =counts!I9*edit_fraction!I9 -> 18.933333 | J9: =counts!J9*edit_fraction!J9 -> 19.076923 | ... V9: =counts!V9*edit_fraction!V9 -> 7.6099707
A10: 9 | B10: G137H | C10: =counts!C10*edit_fraction!C10 -> 132.14565 | D10: =counts!D10*edit_fraction!D10 -> 247.42113 | E10: =counts!E10*edit_fraction!E10 -> 59.946092 | F10: =counts!F10*edit_fraction!F10 -> 194.48276 | G10: =counts!G10*edit_fraction!G10 -> 143.14286 | H10: =counts!H10*edit_fraction!H10 -> 175.42662 | I10: =counts!I10*edit_fraction!I10 -> 168.64533 | J10: =counts!J10*edit_fraction!J10 -> 68.349515 | ... V10: =counts!V10*edit_fraction!V10 -> 274.34328
A11: 10 | B11: G137P | C11: =counts!C11*edit_fraction!C11 -> 1055.3044 | D11: =counts!D11*edit_fraction!D11 -> 673.41046 | E11: =counts!E11*edit_fraction!E11 -> 391.14419 | F11: =counts!F11*edit_fraction!F11 -> 646.25 | G11: =counts!G11*edit_fraction!G11 -> 542.96724 | H11: =counts!H11*edit_fraction!H11 -> 261.30982 | I11: =counts!I11*edit_fraction!I11 -> 373.30498 | J11: =counts!J11*edit_fraction!J11 -> 174.92218 | ... V11: =counts!V11*edit_fraction!V11 -> 198.57877
A12: 11 | B12: G137L | C12: =counts!C12*edit_fraction!C12 -> 47.077333 | D12: =counts!D12*edit_fraction!D12 -> 133.26316 | E12: =counts!E12*edit_fraction!E12 -> 120.9711 | F12: =counts!F12*edit_fraction!F12 -> 108.71508 | G12: =counts!G12*edit_fraction!G12 -> 47.583333 | H12: =counts!H12*edit_fraction!H12 -> 68.808765 | I12: =counts!I12*edit_fraction!I12 -> 47.80786 | J12: =counts!J12*edit_fraction!J12 -> 14.587156 | ... V12: =counts!V12*edit_fraction!V12 -> 55.229358
A13: 12 | B13: G137E | C13: =counts!C13*edit_fraction!C13 -> 211.3408 | D13: =counts!D13*edit_fraction!D13 -> 287.69231 | E13: =counts!E13*edit_fraction!E13 -> 34.057143 | F13: =counts!F13*edit_fraction!F13 -> 109.52962 | G13: =counts!G13*edit_fraction!G13 -> 77.934156 | H13: =counts!H13*edit_fraction!H13 -> 558.16393 | I13: =counts!I13*edit_fraction!I13 -> 361.20321 | J13: =counts!J13*edit_fraction!J13 -> 467.8062 | ... V13: =counts!V13*edit_fraction!V13 -> 86
... A1505: 1556 | B1505: S213R | C1505: =counts!C1505*edit_fraction!C1505 -> 120 | D1505: =counts!D1505*edit_fraction!D1505 -> 29.75 | E1505: =counts!E1505*edit_fraction!E1505 -> 48 | F1505: =counts!F1505*edit_fraction!F1505 -> 93.164021 | G1505: =counts!G1505*edit_fraction!G1505 -> 59.408451 | H1505: =counts!H1505*edit_fraction!H1505 -> 212 | I1505: =counts!I1505*edit_fraction!I1505 -> 36.944444 | J1505: =counts!J1505*edit_fraction!J1505 -> 115 | ... V1505: =counts!V1505*edit_fraction!V1505 -> 137.27103
A1506: 1557 | B1506: 0 | C1506: =counts!C1506*edit_fraction!C1506 -> 35.785714 | D1506: =counts!D1506*edit_fraction!D1506 -> 65.528571 | E1506: =counts!E1506*edit_fraction!E1506 -> 0 | F1506: =counts!F1506*edit_fraction!F1506 -> 38.478261 | G1506: =counts!G1506*edit_fraction!G1506 -> 18.588235 | H1506: =counts!H1506*edit_fraction!H1506 -> 4.6268657 | I1506: =counts!I1506*edit_fraction!I1506 -> 20 | J1506: =counts!J1506*edit_fraction!J1506 -> 0 | ... V1506: =counts!V1506*edit_fraction!V1506 -> 176.20089
A1507: 1558 | B1507: S213I | C1507: =counts!C1507*edit_fraction!C1507 -> 317.37931 | D1507: =counts!D1507*edit_fraction!D1507 -> 286.36923 | E1507: =counts!E1507*edit_fraction!E1507 -> 37.578947 | F1507: =counts!F1507*edit_fraction!F1507 -> 536.06667 | G1507: =counts!G1507*edit_fraction!G1507 -> 191 | H1507: =counts!H1507*edit_fraction!H1507 -> 140 | I1507: =counts!I1507*edit_fraction!I1507 -> 21.333333 | J1507: =counts!J1507*edit_fraction!J1507 -> 0 | ... V1507: =counts!V1507*edit_fraction!V1507 -> 60.257143
A1508: 1559 | B1508: S213M | C1508: =counts!C1508*edit_fraction!C1508 -> 594 | D1508: =counts!D1508*edit_fraction!D1508 -> 478.52994 | E1508: =counts!E1508*edit_fraction!E1508 -> 265.81967 | F1508: =counts!F1508*edit_fraction!F1508 -> 963.65132 | G1508: =counts!G1508*edit_fraction!G1508 -> 587.02413 | H1508: =counts!H1508*edit_fraction!H1508 -> 141.80342 | I1508: =counts!I1508*edit_fraction!I1508 -> 36.111111 | J1508: =counts!J1508*edit_fraction!J1508 -> 12.8 | ... V1508: =counts!V1508*edit_fraction!V1508 -> 264
A1509: 1560 | B1509: S213Q | C1509: =counts!C1509*edit_fraction!C1509 -> 0 | D1509: =counts!D1509*edit_fraction!D1509 -> 0 | E1509: =counts!E1509*edit_fraction!E1509 -> 0 | F1509: =counts!F1509*edit_fraction!F1509 -> 0 | G1509: =counts!G1509*edit_fraction!G1509 -> 0 | H1509: =counts!H1509*edit_fraction!H1509 -> 0 | I1509: =counts!I1509*edit_fraction!I1509 -> 0 | J1509: =counts!J1509*edit_fraction!J1509 -> 0 | ... V1509: =counts!V1509*edit_fraction!V1509 -> 0
A1510: 1561 | B1510: S213H | C1510: =counts!C1510*edit_fraction!C1510 -> 0 | D1510: =counts!D1510*edit_fraction!D1510 -> 0 | E1510: =counts!E1510*edit_fraction!E1510 -> 0 | F1510: =counts!F1510*edit_fraction!F1510 -> 0 | G1510: =counts!G1510*edit_fraction!G1510 -> 0 | H1510: =counts!H1510*edit_fraction!H1510 -> 0 | I1510: =counts!I1510*edit_fraction!I1510 -> 0 | J1510: =counts!J1510*edit_fraction!J1510 -> 0 | ... V1510: =counts!V1510*edit_fraction!V1510 -> 0
A1511: 1562 | B1511: S213P | C1511: =counts!C1511*edit_fraction!C1511 -> 847.57055 | D1511: =counts!D1511*edit_fraction!D1511 -> 867.96067 | E1511: =counts!E1511*edit_fraction!E1511 -> 100.33333 | F1511: =counts!F1511*edit_fraction!F1511 -> 574.27536 | G1511: =counts!G1511*edit_fraction!G1511 -> 464.625 | H1511: =counts!H1511*edit_fraction!H1511 -> 184.78125 | I1511: =counts!I1511*edit_fraction!I1511 -> 30.7125 | J1511: =counts!J1511*edit_fraction!J1511 -> 21 | ... V1511: =counts!V1511*edit_fraction!V1511 -> 33.25
A1512: 1563 | B1512: S213L | C1512: =counts!C1512*edit_fraction!C1512 -> 48.666667 | D1512: =counts!D1512*edit_fraction!D1512 -> 70.19802 | E1512: =counts!E1512*edit_fraction!E1512 -> 87.642857 | F1512: =counts!F1512*edit_fraction!F1512 -> 355.10345 | G1512: =counts!G1512*edit_fraction!G1512 -> 342 | H1512: =counts!H1512*edit_fraction!H1512 -> 2.6707317 | I1512: =counts!I1512*edit_fraction!I1512 -> 41.388889 | J1512: =counts!J1512*edit_fraction!J1512 -> 88 | ... V1512: =counts!V1512*edit_fraction!V1512 -> 131
A1513: 1564 | B1513: S213E | C1513: =counts!C1513*edit_fraction!C1513 -> 28.058824 | D1513: =counts!D1513*edit_fraction!D1513 -> 11.013453 | E1513: =counts!E1513*edit_fraction!E1513 -> 7.7669903 | F1513: =counts!F1513*edit_fraction!F1513 -> 27.453552 | G1513: =counts!G1513*edit_fraction!G1513 -> 14.860335 | H1513: =counts!H1513*edit_fraction!H1513 -> 139.85612 | I1513: =counts!I1513*edit_fraction!I1513 -> 27.279412 | J1513: =counts!J1513*edit_fraction!J1513 -> 0 | ... V1513: =counts!V1513*edit_fraction!V1513 -> 89.28
A1514: 1565 | B1514: S213D | C1514: =counts!C1514*edit_fraction!C1514 -> 420.42 | D1514: =counts!D1514*edit_fraction!D1514 -> 361.30645 | E1514: =counts!E1514*edit_fraction!E1514 -> 136 | F1514: =counts!F1514*edit_fraction!F1514 -> 225.25 | G1514: =counts!G1514*edit_fraction!G1514 -> 74.666667 | H1514: =counts!H1514*edit_fraction!H1514 -> 91.428571 | I1514: =counts!I1514*edit_fraction!I1514 -> 33.703704 | J1514: =counts!J1514*edit_fraction!J1514 -> 0 | ... V1514: =counts!V1514*edit_fraction!V1514 -> 77.744681
A1515: 1566 | B1515: S213A | C1515: =counts!C1515*edit_fraction!C1515 -> 55.809524 | D1515: =counts!D1515*edit_fraction!D1515 -> 106.43443 | E1515: =counts!E1515*edit_fraction!E1515 -> 48.475248 | F1515: =counts!F1515*edit_fraction!F1515 -> 70.943396 | G1515: =counts!G1515*edit_fraction!G1515 -> 54.85567 | H1515: =counts!H1515*edit_fraction!H1515 -> 154.58182 | I1515: =counts!I1515*edit_fraction!I1515 -> 187.14493 | J1515: =counts!J1515*edit_fraction!J1515 -> 0 | ... V1515: =counts!V1515*edit_fraction!V1515 -> 505.13174
A1516: 1567 | B1516: S213G | C1516: =counts!C1516*edit_fraction!C1516 -> 263.21503 | D1516: =counts!D1516*edit_fraction!D1516 -> 334.73646 | E1516: =counts!E1516*edit_fraction!E1516 -> 178.64126 | F1516: =counts!F1516*edit_fraction!F1516 -> 314.98008 | G1516: =counts!G1516*edit_fraction!G1516 -> 194.91076 | H1516: =counts!H1516*edit_fraction!H1516 -> 34 | I1516: =counts!I1516*edit_fraction!I1516 -> 28.08 | J1516: =counts!J1516*edit_fraction!J1516 -> 0 | ... V1516: =counts!V1516*edit_fraction!V1516 -> 126.23729
A1517: 1568 | B1517: S213V | C1517: =counts!C1517*edit_fraction!C1517 -> 99.510204 | D1517: =counts!D1517*edit_fraction!D1517 -> 143.79389 | E1517: =counts!E1517*edit_fraction!E1517 -> 65.606557 | F1517: =counts!F1517*edit_fraction!F1517 -> 283.23248 | G1517: =counts!G1517*edit_fraction!G1517 -> 119.84 | H1517: =counts!H1517*edit_fraction!H1517 -> 57.1875 | I1517: =counts!I1517*edit_fraction!I1517 -> 27.222222 | J1517: =counts!J1517*edit_fraction!J1517 -> 50 | ... V1517: =counts!V1517*edit_fraction!V1517 -> 167.34848
A1518: 1569 | B1518: S213_ | C1518: =counts!C1518*edit_fraction!C1518 -> 78.627907 | D1518: =counts!D1518*edit_fraction!D1518 -> 47.835938 | E1518: =counts!E1518*edit_fraction!E1518 -> 4.1176471 | F1518: =counts!F1518*edit_fraction!F1518 -> 21.875 | G1518: =counts!G1518*edit_fraction!G1518 -> 16.173913 | H1518: =counts!H1518*edit_fraction!H1518 -> 91.636364 | I1518: =counts!I1518*edit_fraction!I1518 -> 41.647059 | J1518: =counts!J1518*edit_fraction!J1518 -> 18.695652 | ... V1518: =counts!V1518*edit_fraction!V1518 -> 486.27451
... A1647: 1698 | B1647: G219F | C1647: =counts!C1647*edit_fraction!C1647 -> 34.934263 | D1647: =counts!D1647*edit_fraction!D1647 -> 47.767405 | E1647: =counts!E1647*edit_fraction!E1647 -> 0 | F1647: =counts!F1647*edit_fraction!F1647 -> 88.721137 | G1647: =counts!G1647*edit_fraction!G1647 -> 14.035088 | H1647: =counts!H1647*edit_fraction!H1647 -> 32.261224 | I1647: =counts!I1647*edit_fraction!I1647 -> 0 | J1647: =counts!J1647*edit_fraction!J1647 -> 0 | ... V1647: =counts!V1647*edit_fraction!V1647 -> 1.5531915
A1649: Sum | C1649: =SUM(C2:C1647) -> 145159.93 | D1649: =SUM(D2:D1647) -> 173776.11 | E1649: =SUM(E2:E1647) -> 66257.835 | F1649: =SUM(F2:F1647) -> 137564.02 | G1649: =SUM(G2:G1647) -> 86521.02 | H1649: =SUM(H2:H1647) -> 111234.69 | I1649: =SUM(I2:I1647) -> 95161.976 | J1649: =SUM(J2:J1647) -> 47904.976 | ... V1649: =SUM(V2:V1647) -> 133675.02
A1650: Overall edit fraction | C1650: =C1649/counts!C1649 -> 0.11900989 | D1650: =D1649/counts!D1649 -> 0.12133195 | E1650: =E1649/counts!E1649 -> 0.099119527 | F1650: =F1649/counts!F1649 -> 0.11482596 | G1650: =G1649/counts!G1649 -> 0.11257256 | H1650: =H1649/counts!H1649 -> 0.11055665 | I1650: =I1649/counts!I1649 -> 0.11151524 | J1650: =J1649/counts!J1649 -> 0.11609725 | ... V1650: =V1649/counts!V1649 -> 0.11074182

Sheet edit_fraction
A1: Index_pegRNA | B1: Target actual | C1: Rep1_B20 | D1: Rep1_B40 | E1: Rep1_Bulk | F1: Rep1_T20 | G1: Rep1_T40 | H1: Rep2_B20 | I1: Rep2_B40 | J1: Rep2_Bulk | K1: Rep2_T20 | L1: Rep2_T40 | M1: Rep3_B20 | N1: Rep3_B40 | O1: Rep3_Bulk | P1: Rep3_T20 | Q1: Rep3_T40 | R1: Rep4_B20 | S1: Rep4_B40 | T1: Rep4_Bulk | U1: Rep4_T20 | V1: Rep4_T40
A2: 1 | B2: G137K | C2: 0.11521739 | D2: 0.068226121 | E2: 0.06010929 | F2: 0.090136054 | G2: 0.15137615 | H2: 0.10288066 | I2: 0.10471204 | J2: 0.015625 | K2: 0.071428571 | L2: 0.16969697 | M2: 0.064371257 | N2: 0.076335878 | O2: 0.067961165 | P2: 0.060836502 | Q2: 0.036585366 | R2: 0.2 | S2: 0.234375 | T2: 0.083011583 | U2: 0.13970588 | V2: 0.13623188
A3: 2 | B3: G137N | C3: 0.15510204 | D3: 0.171875 | E3: 0.12962963 | F3: 0.23267327 | G3: 0.12658228 | H3: 0.18442623 | I3: 0.20806794 | J3: 0.12883436 | K3: 0.10504775 | L3: 0.15533981 | M3: 0.16034483 | N3: 0.12688172 | O3: 0.069478908 | P3: 0.11290323 | Q3: 0.30487805 | R3: 0.3220339 | S3: 0.21621622 | T3: 0.14876033 | U3: 1 | V3: 0.24731183
A4: 3 | B4: G137T | C4: 0.2774427 | D4: 0.21047619 | E4: 0.1556196 | F4: 0.20257235 | G4: 0.29431438 | H4: 0.26007326 | I4: 0.23452158 | J4: 0.22083333 | K4: 0.17165899 | L4: 0.22702703 | M4: 0.36610879 | N4: 0.2439759 | O4: 0.21052632 | P4: 0.15168539 | Q4: 0.12849162 | R4: 0.55838926 | S4: 0.42285714 | T4: 0.48466258 | U4: 0.43317972 | V4: 0.42253521
A5: 4 | B5: G137R | C5: 0.059490085 | D5: 0.072234763 | E5: 0.020920502 | F5: 0.072340426 | G5: 0.023255814 | H5: 0.037344398 | I5: 0.10958904 | J5: 0.0375 | K5: 0.036290323 | L5: 0.059190031 | M5: 0.057692308 | N5: 0.047619048 | O5: 0.055045872 | P5: 0.063063063 | Q5: 0.10588235 | R5: 0.08994709 | S5: 0.12264151 | T5: 0.068728522 | U5: 0.14583333 | V5: 0.14336918
A6: 5 | B6: G137S | C6: 0.14795383 | D6: 0.13508772 | E6: 0.11009174 | F6: 0.15341959 | G6: 0.15410959 | H6: 0.25159236 | I6: 0.29484536 | J6: 0.24946237 | K6: 0.34036939 | L6: 0.34701987 | M6: 0.12510785 | N6: 0.13788487 | O6: 0.1383812 | P6: 0.12093023 | Q6: 0.11656442 | R6: 0.18119266 | S6: 0.2764977 | T6: 0.1459695 | U6: 0.40939597 | V6: 0.25319693
A7: 6 | B7: G137I | C7: 0.19974874 | D7: 0.22562141 | E7: 0.12891986 | F7: 0.31078905 | G7: 0.16926503 | H7: 0.12853774 | I7: 0.12593516 | J7: 0.11704835 | K7: 0.13456221 | L7: 0.13940724 | M7: 0.15691489 | N7: 0.17687075 | O7: 0.083333333 | P7: 0.31927711 | Q7: 0 | R7: 0.13129103 | S7: 0.26666667 | T7: 0.22459893 | U7: 0.16742081 | V7: 0.18198529
A8: 7 | B8: G137M | C8: 0.048979592 | D8: 0.085106383 | E8: 0.052434457 | F8: 0.084507042 | G8: 0.036764706 | H8: 0.071428571 | I8: 0.11555556 | J8: 0.10416667 | K8: 0.125 | L8: 0.071856287 | M8: 0.039215686 | N8: 0.045454545 | O8: 0.046783626 | P8: 0.0051813472 | Q8: 0.070921986 | R8: 0.0875 | S8: 0.040540541 | T8: 0.11258278 | U8: 0.024390244 | V8: 0.083333333
A9: 8 | B9: G137Q | C9: 0.045454545 | D9: 0.016194332 | E9: 0.028037383 | F9: 0.028409091 | G9: 0.0098039216 | H9: 0 | I9: 0.016666667 | J9: 0.076923077 | K9: 0.0078125 | L9: 0.01459854 | M9: 0.0234375 | N9: 0.033333333 | O9: 0.045454545 | P9: 0.038461538 | Q9: 0.016949153 | R9: 0 | S9: 0.020408163 | T9: 0.01369863 | U9: 0.0070422535 | V9: 0.008797654
A10: 9 | B10: G137H | C10: 0.19347826 | D10: 0.24891462 | E10: 0.10781671 | F10: 0.27586207 | G10: 0.28571429 | H10: 0.17064846 | I10: 0.18512111 | J10: 0.15533981 | K10: 0.15279503 | L10: 0.24637681 | M10: 0.18854886 | N10: 0.23945783 | O10: 0.40181269 | P10: 0.25728155 | Q10: 0.15384615 | R10: 0.17738791 | S10: 0.2 | T10: 0.27565084 | U10: 0.32916667 | V10: 0.24626866
A11: 10 | B11: G137P | C11: 0.39421158 | D11: 0.27263581 | E11: 0.33953488 | F11: 0.29712644 | G11: 0.38535645 | H11: 0.22921914 | I11: 0.35722965 | J11: 0.26264591 | K11: 0.26715686 | L11: 0.29988194 | M11: 0.32389289 | N11: 0.27837259 | O11: 0.11203814 | P11: 0.13802817 | Q11: 0.1414791 | R11: 0.2230444 | S11: 0.36 | T11: 0.30161054 | U11: 0.26556017 | V11: 0.25041459
A12: 11 | B12: G137L | C12: 0.034666667 | D12: 0.078947368 | E12: 0.13872832 | F12: 0.078212291 | G12: 0.083333333 | H12: 0.075697211 | I12: 0.061135371 | J12: 0.04587156 | K12: 0.01396648 | L12: 0.088235294 | M12: 0.093137255 | N12: 0.033222591 | O12: 0.10837438 | P12: 0.097087379 | Q12: 0.040816327 | R12: 0.0625 | S12: 0.072727273 | T12: 0.055555556 | U12: 0.082051282 | V12: 0.03058104
A13: 12 | B13: G137E | C13: 0.1318408 | D13: 0.15384615 | E13: 0.038095238 | F13: 0.11131059 | G13: 0.1399177 | H13: 0.30601093 | I13: 0.24339839 | J13: 0.50193798 | K13: 0.33149171 | L13: 0.35102041 | M13: 0.074901445 | N13: 0.025641026 | O13: 0.17491749 | P13: 0.1 | Q13: 0.059602649 | R13: 0.15352697 | S13: 0.042253521 | T13: 0.060606061 | U13: 0.25287356 | V13: 0.12759644
... A15: 14 | B15: G137A | C15: 0.045882353 | D15: 0.096153846 | E15: 0.036093418 | F15: 0.043073341 | G15: 0.082969432 | H15: 0.092627599 | I15: 0.06581741 | J15: 0.034920635 | K15: 0.072763029 | L15: 0.027568922 | M15: 0.13129103 | N15: 0.11323642 | O15: 0.21818182 | P15: 0.13218391 | Q15: 0.031690141 | R15: 0.082954545 | S15: 0.094707521 | T15: 0.050505051 | U15: 0.14798206 | V15: 0.091212458
A16: 15 | B16: G137G | C16: 0 | D16: 0 | E16: 0.014705882 | F16: 0.021978022 | G16: 0 | H16: 0 | I16: 0 | J16: 0 | K16: 0 | L16: 0 | M16: 0 | N16: 0 | P16: 0.03030303 | Q16: 0 | R16: 0.038461538 | S16: 0 | T16: 0.060606061 | U16: 0 | V16: 0
A17: 16 | B17: G137V | C17: 0.096226415 | D17: 0.12452107 | E17: 0.17220544 | F17: 0.19565217 | G17: 0.15789474 | H17: 0.30223881 | I17: 0.082152975 | J17: 0.11783439 | K17: 0.18265683 | L17: 0.087640449 | M17: 0.22338831 | N17: 0.16432866 | O17: 0.34899329 | P17: 0.057377049 | Q17: 0.10734463 | R17: 0.21228304 | S17: 0.23970037 | T17: 0.19952494 | U17: 0.116 | V17: 0.20281124
A18: 17 | B18: G137_ | C18: 0.056195965 | D18: 0.11111111 | E18: 0.026726058 | F18: 0.084394904 | G18: 0.071691176 | H18: 0.094986807 | I18: 0.050847458 | J18: 0.098765432 | K18: 0.078431373 | L18: 0.058219178 | M18: 0.041899441 | N18: 0.10434783 | O18: 0.014184397 | P18: 0.021164021 | Q18: 0.028301887 | R18: 0.10964912 | S18: 0.085858586 | T18: 0.035897436 | U18: 0.047619048 | V18: 0.087264151
A19: 18 | B19: G137Y | C19: 0.135778 | D19: 0.13718622 | E19: 0.21313364 | F19: 0.11077236 | G19: 0.13772455 | H19: 0.31503378 | I19: 0.17655572 | J19: 0.21576763 | K19: 0.24132139 | L19: 0.28006088 | M19: 0.35885538 | N19: 0.26396761 | O19: 0.13616071 | P19: 0.1878453 | Q19: 0.07310705 | R19: 0.18458274 | S19: 0.28650138 | T19: 0.23719958 | U19: 0.1403118 | V19: 0.17631103
A20: 19 | B20: G137C | C20: 0.094170404 | D20: 0.1872705 | E20: 0.095115681 | F20: 0.13888889 | G20: 0.082568807 | H20: 0.25879917 | I20: 0.29963899 | J20: 0.57920792 | K20: 0.32458564 | L20: 0.25959781 | M20: 0.18084066 | N20: 0.24290484 | O20: 0.14222222 | P20: 0.18411552 | Q20: 0.081939799 | R20: 0.19246862 | S20: 0.12149533 | T20: 0.2039801 | U20: 0.19815668 | V20: 0.056726094
A21: 20 | B21: G137W | C21: 0.19093851 | D21: 0.13216561 | E21: 0.059190031 | F21: 0.094420601 | G21: 0.12745098 | H21: 0.12435233 | I21: 0.14539007 | J21: 0.24793388 | K21: 0.069105691 | L21: 0.11805556 | M21: 0.11641791 | N21: 0.11674009 | O21: 0.086092715 | P21: 0.18421053 | Q21: 0.062176166 | R21: 0.14285714 | S21: 0.29375 | T21: 0.13682093 | U21: 0.13291139 | V21: 0.155902
A22: 21 | B22: G137F | C22: 0.19773096 | D22: 0.13483146 | E22: 0.13767343 | F22: 0.17313916 | G22: 0.14246947 | H22: 0.10921502 | I22: 0.080508475 | J22: 0.16622691 | K22: 0.14069767 | L22: 0.1206544 | M22: 0.29485571 | N22: 0.1048951 | O22: 0.14146341 | P22: 0.22994652 | Q22: 0.24747475 | R22: 0.31015453 | S22: 0.25868726 | T22: 0.40069085 | U22: 0.25524476 | V22: 0.354
A23: 22 | B23: S138K | C23: 0 | D23: 0 | F23: 0 | G23: 0 | H23: 0 | I23: 0 | J23: 0 | K23: 0 | L23: 0 | M23: 0 | N23: 0 | O23: 0 | P23: 0 | Q23: 0 | R23: 0 | S23: 0 | T23: 0 | U23: 0 | V23: 0
A24: 23 | B24: S138N | C24: 0 | D24: 0 | E24: 0 | F24: 0 | G24: 0 | H24: 0 | I24: 0 | J24: 0.33333333 | K24: 0 | L24: 0 | M24: 0 | N24: 0 | O24: 0 | P24: 0 | R24: 0 | S24: 0 | T24: 0.035714286 | U24: 0 | V24: 0
A25: 24 | B25: S138T | C25: 0 | D25: 0 | F25: 0 | G25: 0 | H25: 0 | I25: 0 | L25: 0 | M25: 0 | N25: 0 | O25: 0 | P25: 0 | R25: 0 | V25: 0
A26: 25 | B26: S138R | C26: 0 | D26: 0 | E26: 0.010752688 | F26: 0 | G26: 0.0097087379 | H26: 0 | I26: 0 | K26: 0 | L26: 1 | N26: 0 | R26: 0 | S26: 0.0073529412 | T26: 0 | U26: 0 | V26: 0
A27: 26 | B27: S138S | C27: 0 | D27: 0 | E27: 0 | F27: 0 | G27: 0 | H27: 0 | J27: 0 | K27: 0 | L27: 0 | M27: 0 | N27: 0 | P27: 0 | Q27: 0 | R27: 0 | S27: 0 | T27: 0 | U27: 0 | V27: 0
A28: 27 | B28: S138I | D28: 0 | E28: 0 | H28: 0 | I28: 0 | J28: 0 | K28: 0 | L28: 0 | M28: 0 | N28: 0 | O28: 0 | Q28: 0 | R28: 0 | S28: 0 | U28: 0 | V28: 0
A29: 28 | B29: S138M | C29: 0 | D29: 0 | E29: 0 | F29: 0 | G29: 0 | H29: 0 | I29: 0 | J29: 0 | K29: 0 | L29: 0 | M29: 0 | N29: 0 | P29: 0 | Q29: 0 | R29: 0 | S29: 0 | T29: 0 | U29: 0 | V29: 0
A30: 29 | B30: S138Q | C30: 0 | D30: 0 | F30: 0 | G30: 0 | H30: 0 | I30: 0 | J30: 0 | K30: 0 | L30: 0 | M30: 0 | N30: 0 | O30: 0 | P30: 0 | Q30: 0.047619048 | R30: 0 | U30: 0 | V30: 0
A31: 30 | B31: S138H | C31: 0 | D31: 0 | E31: 0 | F31: 0 | G31: 0 | H31: 0 | I31: 0 | J31: 0 | L31: 0 | O31: 0 | R31: 0.076923077 | S31: 0 | T31: 0 | U31: 0 | V31: 0
A32: 31 | B32: S138P | C32: 0 | D32: 0 | F32: 0 | G32: 0 | I32: 0 | J32: 0 | L32: 1 | M32: 0 | N32: 0 | O32: 0 | P32: 0 | Q32: 0 | R32: 0 | S32: 0 | V32: 0
A33: 32 | B33: S138L | C33: 0 | D33: 0 | E33: 0 | F33: 0 | G33: 0 | H33: 0 | I33: 0 | K33: 0 | M33: 0 | N33: 0 | O33: 0 | P33: 0.5 | R33: 0 | S33: 0 | U33: 0 | V33: 0
A34: 33 | B34: S138E | C34: 0 | D34: 0 | E34: 0 | F34: 0 | G34: 0 | H34: 0 | I34: 0 | J34: 0 | K34: 0 | L34: 0.035714286 | M34: 0 | N34: 0 | O34: 0 | P34: 0 | Q34: 0 | S34: 0 | T34: 0 | U34: 0 | V34: 0
A35: 34 | B35: S138D | C35: 0 | D35: 0 | E35: 0 | F35: 0 | G35: 0 | H35: 0 | I35: 0 | J35: 0 | K35: 0 | L35: 0 | M35: 0 | N35: 0 | P35: 0 | Q35: 1 | R35: 0 | S35: 0 | T35: 0 | U35: 0 | V35: 0
A36: 35 | B36: S138A | C36: 0 | D36: 0 | E36: 0 | F36: 0 | H36: 0 | I36: 0 | K36: 0 | L36: 0 | M36: 0 | N36: 0 | P36: 0 | Q36: 0 | R36: 0 | S36: 0 | T36: 0.2 | U36: 0 | V36: 0
A37: 36 | B37: S138G | C37: 0 | D37: 0 | E37: 0 | F37: 0 | G37: 0 | H37: 0 | J37: 0 | M37: 0 | N37: 0 | Q37: 0 | R37: 0 | S37: 0 | T37: 0 | U37: 0 | V37: 0
A38: 37 | B38: S138V | C38: 0 | D38: 0 | E38: 0 | F38: 0 | G38: 0 | H38: 0 | I38: 0 | J38: 0 | K38: 0 | L38: 0 | M38: 0 | N38: 0 | O38: 0 | P38: 0 | Q38: 0 | R38: 0.047619048 | S38: 0 | T38: 0.043478261 | U38: 0 | V38: 0
A39: 38 | B39: S138_ | C39: 0 | D39: 0 | E39: 0 | F39: 0 | G39: 0 | H39: 0 | I39: 0 | J39: 0.015151515 | K39: 0 | L39: 0 | N39: 0 | O39: 0 | P39: 0 | V39: 0
A40: 39 | B40: S138Y | C40: 0.0125 | D40: 0 | E40: 0 | F40: 0 | G40: 0 | H40: 0 | I40: 0 | J40: 0 | K40: 0 | L40: 0 | M40: 0 | N40: 0 | O40: 0 | P40: 0 | Q40: 0 | R40: 0 | S40: 0 | T40: 0.055555556
A41: 40 | B41: S138C | C41: 0 | E41: 0 | F41: 0 | H41: 0 | I41: 0 | K41: 0 | L41: 0 | M41: 0 | N41: 0 | O41: 0 | P41: 0 | Q41: 0 | R41: 0 | T41: 0 | V41: 0
...
